(node:3700) UnhandledPromiseRejectionWarning: MongoNetworkError: failed to connect to server [127.0.0.1:27017] on first connect [MongoNetworkError: connect ECONNREFUSED 127.0.0.1:27017]
    at Pool.<anonymous> (D:\TFS\UGPS\UGPS.NodeAPI\node_modules\mongodb-core\lib\topologies\server.js:505:11)
    at Pool.emit (events.js:180:13)
    at Connection.<anonymous> (D:\TFS\UGPS\UGPS.NodeAPI\node_modules\mongodb-core\lib\connection\pool.js:329:12)
    at Object.onceWrapper (events.js:272:13)
    at Connection.emit (events.js:180:13)
    at Socket.<anonymous> (D:\TFS\UGPS\UGPS.NodeAPI\node_modules\mongodb-core\lib\connection\connection.js:245:50)
    at Object.onceWrapper (events.js:272:13)
    at Socket.emit (events.js:180:13)
    at emitErrorNT (internal/streams/destroy.js:64:8)
    at process._tickCallback (internal/process/next_tick.js:114:19)
(node:3700) UnhandledPromiseRejectionWarning: Unhandled promise rejection. This error originated either by throwing inside of an async function without a catch block, or by rejecting a promise which was not handled with .catch(). (rejection id: 1)
(node:3700) [DEP0018] DeprecationWarning: Unhandled promise rejections are deprecated. In the future, promise rejections that are not handled will terminate the Node.js process with a non-zero exit code.
(node:3700) UnhandledPromiseRejectionWarning: MongoNetworkError: failed to connect to server [127.0.0.1:27017] on first connect [MongoNetworkError: connect ECONNREFUSED 127.0.0.1:27017]
    at Pool.<anonymous> (D:\TFS\UGPS\UGPS.NodeAPI\node_modules\mongodb-core\lib\topologies\server.js:505:11)
    at Pool.emit (events.js:180:13)
    at Connection.<anonymous> (D:\TFS\UGPS\UGPS.NodeAPI\node_modules\mongodb-core\lib\connection\pool.js:329:12)
    at Object.onceWrapper (events.js:272:13)
    at Connection.emit (events.js:180:13)
    at Socket.<anonymous> (D:\TFS\UGPS\UGPS.NodeAPI\node_modules\mongodb-core\lib\connection\connection.js:245:50)
    at Object.onceWrapper (events.js:272:13)
    at Socket.emit (events.js:180:13)
    at emitErrorNT (internal/streams/destroy.js:64:8)
    at process._tickCallback (internal/process/next_tick.js:114:19)
(node:3700) UnhandledPromiseRejectionWarning: Unhandled promise rejection. This error originated either by throwing inside of an async function without a catch block, or by rejecting a promise which was not handled with .catch(). (rejection id: 2)
